(dp1
S'output'
p2
S'<type \'exceptions.RuntimeError\'> Failure to connect, tried 5 times:\nTraceback (most recent call last):\n  File "/opt/web2py/gluon/packages/dal/pydal/base.py", line 457, in __init__\n    self._adapter = adapter(**kwargs)\n  File "/opt/web2py/gluon/packages/dal/pydal/adapters/__init__.py", line 39, in __call__\n    obj = super(AdapterMeta, cls).__call__(*args, **kwargs)\n  File "/opt/web2py/gluon/packages/dal/pydal/adapters/base.py", line 369, in __init__\n    super(SQLAdapter, self).__init__(*args, **kwargs)\n  File "/opt/web2py/gluon/packages/dal/pydal/adapters/base.py", line 53, in __init__\n    self.reconnect()\n  File "/opt/web2py/gluon/packages/dal/pydal/connection.py", line 174, in reconnect\n    self.connection = self.connector()\n  File "/opt/web2py/gluon/packages/dal/pydal/adapters/mysql.py", line 51, in connector\n    return self.driver.connect(**self.driver_args)\n  File "/opt/web2py/gluon/contrib/pymysql/__init__.py", line 90, in Connect\n    return Connection(*args, **kwargs)\n  File "/opt/web2py/gluon/contrib/pymysql/connections.py", line 688, in __init__\n    self.connect()\n  File "/opt/web2py/gluon/contrib/pymysql/connections.py", line 937, in connect\n    raise exc\nOperationalError: (2003, "Can\'t connect to MySQL server on \'35.242.141.119\' ([Errno 111] Connection refused)")\n'
p3
sS'layer'
p4
S'/opt/web2py/applications/datalake/models/db.py'
p5
sS'code'
p6
S'<code object <module> at 0x7fd504d50330, file "/opt/web2py/applications/datalake/models/db.py", line 7>'
p7
sS'snapshot'
p8
(dp9
sS'traceback'
p10
S'Traceback (most recent call last):\n  File "/opt/web2py/gluon/restricted.py", line 219, in restricted\n    exec(ccode, environment)\n  File "/opt/web2py/applications/datalake/models/db.py", line 36, in <module>\n    check_reserved=[\'all\'])\n  File "/opt/web2py/gluon/packages/dal/pydal/base.py", line 171, in __call__\n    obj = super(MetaDAL, cls).__call__(*args, **kwargs)\n  File "/opt/web2py/gluon/packages/dal/pydal/base.py", line 477, in __init__\n    "Failure to connect, tried %d times:\\n%s" % (attempts, tb)\nRuntimeError: Failure to connect, tried 5 times:\nTraceback (most recent call last):\n  File "/opt/web2py/gluon/packages/dal/pydal/base.py", line 457, in __init__\n    self._adapter = adapter(**kwargs)\n  File "/opt/web2py/gluon/packages/dal/pydal/adapters/__init__.py", line 39, in __call__\n    obj = super(AdapterMeta, cls).__call__(*args, **kwargs)\n  File "/opt/web2py/gluon/packages/dal/pydal/adapters/base.py", line 369, in __init__\n    super(SQLAdapter, self).__init__(*args, **kwargs)\n  File "/opt/web2py/gluon/packages/dal/pydal/adapters/base.py", line 53, in __init__\n    self.reconnect()\n  File "/opt/web2py/gluon/packages/dal/pydal/connection.py", line 174, in reconnect\n    self.connection = self.connector()\n  File "/opt/web2py/gluon/packages/dal/pydal/adapters/mysql.py", line 51, in connector\n    return self.driver.connect(**self.driver_args)\n  File "/opt/web2py/gluon/contrib/pymysql/__init__.py", line 90, in Connect\n    return Connection(*args, **kwargs)\n  File "/opt/web2py/gluon/contrib/pymysql/connections.py", line 688, in __init__\n    self.connect()\n  File "/opt/web2py/gluon/contrib/pymysql/connections.py", line 937, in connect\n    raise exc\nOperationalError: (2003, "Can\'t connect to MySQL server on \'35.242.141.119\' ([Errno 111] Connection refused)")\n\n'
p11
s.